Workbook

Sheet اقرأني
A1: Styllano — Color System
A2: اتسحب من شوبيفاي (products.json): 620 منتج، 2032 صف لون، 253 قيمة لون مختلفة ← 66 لون موحد + 46 لون مزدوج.
A4: Standard Colors: كل لون موحد مرة واحدة، وجنبه كل الأسماء اللي متكتب بيها حالياً. ده الجدول الأساسي.
A5: All Values: كل قيمة لون زي ما هي في شوبيفاي ← الاسم الموحد المقترح.
A6: Products: كل منتج × لون، مع لينك الأدمن ولينك Vendoor. عمود "اللون في Vendoor" الأصفر هيتملى لما ملف Vendoor يوصل.
A7: Option Names: أسماء الـoption نفسها (Color / Colors / الالوان...) — لازم تتوحد.
A9: ألوان عمود الحالة:
A10: أخضر = سليم | برتقالي فاتح = غلط كتابة أو عربي | أصفر = اسم تاني لنفس اللون | أحمر فاتح = محتاج تبص عليه بعينك | أزرق = لون مزدوج | رمادي = مش لون
A12: قاعدة الألوان المزدوجة المقترحة: "Black & White" (اللون الأساسي الأول). مش "/" عشان شوبيفاي بيستخدم "/" بين الـoptions في اسم الـvariant.
A13: تفاصيل زي Logo / Stripes / Sole مكانها الوصف أو الصور، مش اسم اللون.
A14: الأسماء في "محتاج مراجعة" اقتراحات مني — لو الدرجتين مختلفين فعلاً قدام الزبون، ما تدمجهمش.
A16: مطابقة Vendoor
... A29: Products: اتضاف 3 أعمدة: اللون في Vendoor (موحد)، المطابقة، ملاحظة المطابقة.

Sheet To Fix
A1: المنتج | B1: لينك الأدمن | C1: اللون في شوبيفاي | D1: اللون في Vendoor | E1: Vendoor (موحد) | F1: المشكلة | G1: التفاصيل | H1: لينك Vendoor
A2: Adidas Clog Slides | B2: فتح | C2: Biege | D2: — المنتج اتشال من Vendoor (404) | F2: ⛔ المنتج اتشال من Vendoor | H2: https://aff.ven-door.com/product/4816
A3: Adidas Clog Slides | B3: فتح | C3: Black | D3: — المنتج اتشال من Vendoor (404) | F3: ⛔ المنتج اتشال من Vendoor | H3: https://aff.ven-door.com/product/4816
A4: Adidas Clog Slides | B4: فتح | C4: Khaki | D4: — المنتج اتشال من Vendoor (404) | F4: ⛔ المنتج اتشال من Vendoor | H4: https://aff.ven-door.com/product/4816
A5: Adidas Men’s Lightweight Sneakers | B5: فتح | C5: Black | D5: — المنتج اتشال من Vendoor (404) | F5: ⛔ المنتج اتشال من Vendoor | H5: https://aff.ven-door.com/product/4448
A6: Adidas Men’s Lightweight Sneakers | B6: فتح | C6: Gray | D6: — المنتج اتشال من Vendoor (404) | F6: ⛔ المنتج اتشال من Vendoor | H6: https://aff.ven-door.com/product/4448
A7: Adidas Men’s Lightweight Sneakers | B7: فتح | C7: Navy | D7: — المنتج اتشال من Vendoor (404) | F7: ⛔ المنتج اتشال من Vendoor | H7: https://aff.ven-door.com/product/4448
A8: Adidas Sweatpants | B8: فتح | C8: Black | D8: — المنتج اتشال من Vendoor (404) | F8: ⛔ المنتج اتشال من Vendoor | H8: https://aff.ven-door.com/product/4965
A9: Adidas Sweatpants | B9: فتح | C9: Silver | D9: — المنتج اتشال من Vendoor (404) | F9: ⛔ المنتج اتشال من Vendoor | H9: https://aff.ven-door.com/product/4965
A10: Adidas Tracksuit | B10: فتح | C10: Beige | D10: — المنتج اتشال من Vendoor (404) | F10: ⛔ المنتج اتشال من Vendoor | H10: https://aff.ven-door.com/product/5209
A11: Adidas Tracksuit | B11: فتح | C11: Brown | D11: — المنتج اتشال من Vendoor (404) | F11: ⛔ المنتج اتشال من Vendoor | H11: https://aff.ven-door.com/product/5209
A12: Adidas Tracksuit | B12: فتح | C12: Grey | D12: — المنتج اتشال من Vendoor (404) | F12: ⛔ المنتج اتشال من Vendoor | H12: https://aff.ven-door.com/product/5209
A13: Adidas Tracksuit | B13: فتح | C13: Mint Green | D13: — المنتج اتشال من Vendoor (404) | F13: ⛔ المنتج اتشال من Vendoor | H13: https://aff.ven-door.com/product/5209
... A73: ZARA Slip-On Summer Shoes | B73: فتح | C73: Stars | D73: — مش موجود على Vendoor | F73: ⛔ اللون مش موجود على Vendoor | H73: https://aff.ven-door.com/product/5316
A74: 3D Teddy Bear EVA Slipper | B74: فتح | C74: Brown | D74: كاكاو | E74: Cocoa | F74: ❌ مختلف | G74: شوبيفاي: Brown ← Vendoor: كاكاو | H74: https://aff.ven-door.com/product/5877
A75: AMR Diab Off White Cotton Shirt | B75: فتح | C75: Off White | D75: ابيض | E75: White | F75: ❌ مختلف | G75: شوبيفاي: Off White ← Vendoor: ابيض | H75: https://aff.ven-door.com/product/5214
A76: ARC Men's Casual Slip-On Shoe | B76: فتح | C76: Havan | D76: جملي | E76: Camel | F76: ❌ مختلف | G76: شوبيفاي: Havan ← Vendoor: جملي | H76: https://aff.ven-door.com/product/5979
A77: Adidas Gazelle Everyday Shoes | B77: فتح | C77: Light Blue | D77: لبني | E77: Baby Blue | F77: ❌ مختلف | G77: شوبيفاي: Light Blue ← Vendoor: لبني — لبني = Baby Blue (15) بس اتكتب Light Blue (7) — لازم اسم واحد | H77: Adidas Gazelle Sneaker FL18 ( مخزن 301 ) - لبني 41
A78: Amr Diab Signature Off-White Chemise | B78: فتح | C78: Off White | D78: ابيض | E78: White | F78: ❌ مختلف | G78: شوبيفاي: Off White ← Vendoor: ابيض | H78: https://aff.ven-door.com/product/5215
A79: Braided Platform Sandal | B79: فتح | C79: Aqua | D79: تركواز | E79: Turquoise | F79: ❌ مختلف | G79: شوبيفاي: Aqua ← Vendoor: تركواز | H79: https://aff.ven-door.com/product/5452
A80: Braided Platform Sandal | B80: فتح | C80: Light Blue | D80: لبني | E80: Baby Blue | F80: ❌ مختلف | G80: شوبيفاي: Light Blue ← Vendoor: لبني — لبني = Baby Blue (15) بس اتكتب Light Blue (7) — لازم اسم واحد | H80: https://aff.ven-door.com/product/5452
A81: Cargo Denim Jogger | B81: فتح | C81: Baby Blue | D81: لبني فاتح | E81: Light Blue | F81: ❌ مختلف | G81: شوبيفاي: Baby Blue ← Vendoor: لبني فاتح — اتكتب Baby Blue 3 مرات و Light Blue مرة | H81: https://aff.ven-door.com/product/5082
A82: Cargo Denim Jogger | B82: فتح | C82: Gray | D82: رمادي فاتح | E82: Light Gray | F82: ❌ مختلف | G82: شوبيفاي: Gray ← Vendoor: رمادي فاتح | H82: https://aff.ven-door.com/product/5082
A83: Classic Gabardine Pants | B83: فتح | C83: Gray | D83: رصاصي غامق | E83: Dark Gray | F83: ❌ مختلف | G83: شوبيفاي: Gray ← Vendoor: رصاصي غامق | H83: https://aff.ven-door.com/product/5062
A84: Classic Leather Slipper | B84: فتح | C84: Khaki | D84: كموني | E84: Cumin | F84: ❌ مختلف | G84: شوبيفاي: Khaki ← Vendoor: كموني — اتكتب Camel 3 مرات و Khaki مرتين — لون مختلف عنهم | H84: https://aff.ven-door.com/product/4915
A85: Cotton Oxford Shirt | B85: فتح | C85: Terracotta | D85: طوبي | E85: Brick | F85: ❌ مختلف | G85: شوبيفاي: Terracotta ← Vendoor: طوبي — اتكتب Brick و Terracotta | H85: https://aff.ven-door.com/product/4910
... A153: Women’s Puma Comfort Sneakers | B153: فتح | C153: Burgundy × Olive × Beige | D153: بيج | E153: Beige | F153: ◐ Vendoor كاتب جزء من اللون | G153: شوبيفاي: Burgundy × Olive × Beige ← Vendoor: بيج | H153: https://aff.ven-door.com/product/5334
A154: Imported Sky Leather Shoes | B154: فتح | C154: Black * White | D154: ابيض تطعيم اسود | E154: White & Black | F154: ↔ نفس الألوان، ترتيب مختلف | H154: https://aff.ven-door.com/product/5318

Sheet Standard Colors
A1: Standard name (الاسم الموحد) | B1: النوع | C1: عدد المنتجات | D1: عدد الأسماء المختلفة | E1: الأسماء الموجودة حالياً (وعدد المنتجات) | F1: ملاحظات / محتاج مراجعة | G1: الاسم في Vendoor (وعدد الصفوف)
A2: Black | B2: لون | C2: =COUNTIF(Products!$F$2:$F$2033,A2) | D2: 10 | E2: Black (437) | اسود (3) | Black×Black (2) | Black & Tiger (1) | Black with Leather Accent (1) | Black Burnished (1) | Black with Black Stripes (1) | Black suede (1) | أسود (1) | Matte Black (1) | F2: ⚠ فيه أسماء محتاجة تتأكد منها بعينك / التفاصيل (Leather Accent) مكانها الوصف مش اسم اللون / التفاصيل (Stripes) مكانها الوصف مش اسم اللون / التفاصيل (Tiger) مكانها الوصف مش اسم اللون / دي خامة/تشطيب مش لون | G2: اسود (446) | اسود خطوط سوداء (1) | اسود فرنيه (1) | اسود تطعيم جلد (1) | اسود ناعم (1)
A3: White | B3: لون | C3: =COUNTIF(Products!$F$2:$F$2033,A3) | D3: 6 | E3: White (219) | Wihte (5) | White. (1) | White with White Stripes (1) | white (1) | ابيض (1) | F3: ⚠ فيه أسماء محتاجة تتأكد منها بعينك / التفاصيل (Stripes) مكانها الوصف مش اسم اللون | G3: ابيض (227) | ابيض خطوط ابيض (1)
A4: Gray | B4: لون | C4: =COUNTIF(Products!$F$2:$F$2033,A4) | D4: 4 | E4: Gray (124) | Grey (30) | رمادي (2) | رصاصي (1) | F4: ⚠ فيه أسماء محتاجة تتأكد منها بعينك | G4: رمادي (143) | رصاصي (23) | حديدي (1)
A5: Beige | B5: لون | C5: =COUNTIF(Products!$F$2:$F$2033,A5) | D5: 6 | E5: Beige (117) | Baige (3) | Biege (3) | Bagie (2) | ييج (1) | Beige Striped (1) | F5: ⚠ فيه أسماء محتاجة تتأكد منها بعينك / التفاصيل (Striped) مكانها الوصف مش اسم اللون | G5: بيج (126)
A6: Navy | B6: لون | C6: =COUNTIF(Products!$F$2:$F$2033,A6) | D6: 4 | E6: Navy (124) | Navy Blue (1) | Navy Stars (1) | كحلي (1) | F6: ⚠ فيه أسماء محتاجة تتأكد منها بعينك / التفاصيل (Stars) مكانها الوصف مش اسم اللون | G6: كحلي (129) | ستارز كحلي (1)
A7: Brown | B7: لون | C7: =COUNTIF(Products!$F$2:$F$2033,A7) | D7: 6 | E7: Brown (108) | Brwon (4) | Brawn (2) | بني (2) | Brown with Leather Accent (1) | Brown suede (1) | F7: ⚠ فيه أسماء محتاجة تتأكد منها بعينك / التفاصيل (Leather Accent) مكانها الوصف مش اسم اللون / دي خامة/تشطيب مش لون | G7: بني (121) | بني تطعيم جلد (1)
A8: Olive | B8: لون | C8: =COUNTIF(Products!$F$2:$F$2033,A8) | D8: 3 | E8: Olive (38) | Olive Green (20) | Olive Stars (1) | F8: ⚠ فيه أسماء محتاجة تتأكد منها بعينك / التفاصيل (Stars) مكانها الوصف مش اسم اللون | G8: زيتي (53) | زتوني (7)
A9: Havana | B9: لون | C9: =COUNTIF(Products!$F$2:$F$2033,A9) | D9: 4 | E9: Havan (29) | Havana (24) | Havana Brown (3) | هافان (2) | F9: ⚠ فيه أسماء محتاجة تتأكد منها بعينك | G9: هافان (54)
A10: Blue | B10: لون | C10: =COUNTIF(Products!$F$2:$F$2033,A10) | D10: 1 | E10: Blue (51) | G10: ازرق (52)
A11: Red | B11: لون | C11: =COUNTIF(Products!$F$2:$F$2033,A11) | D11: 1 | E11: Red (46) | G11: احمر (46)
A12: Gold | B12: لون | C12: =COUNTIF(Products!$F$2:$F$2033,A12) | D12: 4 | E12: Gold (37) | Cold (1) | Gold 18 (1) | Gold 20 (1) | F12: ⚠ فيه أسماء محتاجة تتأكد منها بعينك / الرقم ده عيار مش لون — حطه في option تاني / غالباً غلطة في Gold — اتأكد | G12: جولد (40) | ذهبي (1)
A13: Pink | B13: لون | C13: =COUNTIF(Products!$F$2:$F$2033,A13) | D13: 3 | E13: Pink (28) | pink (2) | PINK (1) | G13: بينك (30) | زهري (1)
A14: Burgundy | B14: لون | C14: =COUNTIF(Products!$F$2:$F$2033,A14) | D14: 3 | E14: Burgundy (20) | Burgandy (8) | Burgany (2) | G14: نبيتي (23) | برجندي (7)
A15: Baby Blue | B15: لون | C15: =COUNTIF(Products!$F$2:$F$2033,A15) | D15: 2 | E15: Baby Blue (26) | Baby blue (1) | G15: لبني (22) | بيبي بلو (10)
A16: Dark Gray | B16: لون | C16: =COUNTIF(Products!$F$2:$F$2033,A16) | D16: 3 | E16: Dark Gray (16) | Dark Grey (8) | Dark gray (1) | G16: رمادي غامق (12) | رصاصي غامق (12)
A17: Mint Green | B17: لون | C17: =COUNTIF(Products!$F$2:$F$2033,A17) | D17: 2 | E17: Mint Green (21) | Mint (3) | F17: ⚠ فيه أسماء محتاجة تتأكد منها بعينك | G17: مينت جرين (16) | منت جرين (3) | منت (1)
A18: Silver | B18: لون | C18: =COUNTIF(Products!$F$2:$F$2033,A18) | D18: 2 | E18: Silver (23) | Selver (1) | G18: سيلفر (10) | فضي (10) | سلفر (4)
A19: Cashmere | B19: لون | C19: =COUNTIF(Products!$F$2:$F$2033,A19) | D19: 3 | E19: Cashmere (14) | Kashmir (8) | Cashmir (1) | G19: كشمير (22)
A20: Camel | B20: لون | C20: =COUNTIF(Products!$F$2:$F$2033,A20) | D20: 3 | E20: Camel (19) | Gamel (1) | Gamal (1) | G20: جملي (19)
A21: Yellow | B21: لون | C21: =COUNTIF(Products!$F$2:$F$2033,A21) | D21: 2 | E21: Yellow (20) | yellow (1) | G21: اصفر (22)
A22: Petrol | B22: لون | C22: =COUNTIF(Products!$F$2:$F$2033,A22) | D22: 2 | E22: Petrol (15) | Petrol Blue (4) | G22: بترولي (17)
A23: Off White | B23: لون | C23: =COUNTIF(Products!$F$2:$F$2033,A23) | D23: 2 | E23: Off White (16) | Off-White (1) | G23: اوف وايت (13)
A24: Green | B24: لون | C24: =COUNTIF(Products!$F$2:$F$2033,A24) | D24: 1 | E24: Green (16) | G24: اخضر (15)
A25: Light Gray | B25: لون | C25: =COUNTIF(Products!$F$2:$F$2033,A25) | D25: 2 | E25: Light Grey (11) | Light Gray (5) | G25: رمادي فاتح (14) | رصاصي فاتح (3)
A26: Mauve | B26: لون | C26: =COUNTIF(Products!$F$2:$F$2033,A26) | D26: 3 | E26: Mauve (8) | Mouve (3) | Muve (1) | G26: موف (13)
A27: Light Blue | B27: لون | C27: =COUNTIF(Products!$F$2:$F$2033,A27) | D27: 1 | E27: Light Blue (9) | G27: لبني فاتح (4)
A28: Coffee | B28: لون | C28: =COUNTIF(Products!$F$2:$F$2033,A28) | D28: 2 | E28: Coffee (6) | Caffe (1) | G28: كافيه (7)
A29: Fuchsia | B29: لون | C29: =COUNTIF(Products!$F$2:$F$2033,A29) | D29: 1 | E29: Fuchsia (7) | G29: فوشيا (7)
A30: Turquoise | B30: لون | C30: =COUNTIF(Products!$F$2:$F$2033,A30) | D30: 2 | E30: Turquoise (6) | Turquoise Blue (1) | G30: تركواز (7) | فيروزي (3)
A31: Denim Blue | B31: لون | C31: =COUNTIF(Products!$F$2:$F$2033,A31) | D31: 3 | E31: Jeans (3) | Blue Denim (2) | Denim Blue (1) | F31: ⚠ فيه أسماء محتاجة تتأكد منها بعينك | G31: جينز (3) | لون جينز (3)
A32: Mango | B32: لون | C32: =COUNTIF(Products!$F$2:$F$2033,A32) | D32: 2 | E32: Mango (5) | منجاوي (1) | G32: منجاوي (5)
A33: Purple | B33: لون | C33: =COUNTIF(Products!$F$2:$F$2033,A33) | D33: 1 | E33: Purple (6) | G33: بنفسجي (4)
A34: Pepsi | B34: لون | C34: =COUNTIF(Products!$F$2:$F$2033,A34) | D34: 2 | E34: Pepsi (4) | Pepsi Blue (1) | G34: بيبسي (5)
A35: Mustard | B35: لون | C35: =COUNTIF(Products!$F$2:$F$2033,A35) | D35: 2 | E35: Mustard (3) | Mustarda (1) | G35: مسترده (4)
A36: Orange | B36: لون | C36: =COUNTIF(Products!$F$2:$F$2033,A36) | D36: 1 | E36: Orange (4) | G36: اورانج (4)
A37: Pistachio | B37: لون | C37: =COUNTIF(Products!$F$2:$F$2033,A37) | D37: 1 | E37: Pistachio (4) | G37: بستشيو (4)
A38: Cocoa | B38: لون | C38: =COUNTIF(Products!$F$2:$F$2033,A38) | D38: 1 | E38: Cocoa (3) | F38: ⚠ فيه أسماء محتاجة تتأكد منها بعينك | G38: كاكاو (4)
A39: Firani | B39: لون | C39: =COUNTIF(Products!$F$2:$F$2033,A39) | D39: 1 | E39: Firani (3) | F39: ⚠ فيه أسماء محتاجة تتأكد منها بعينك | G39: فيراني (3)
A40: Genzari | B40: لون | C40: =COUNTIF(Products!$F$2:$F$2033,A40) | D40: 2 | E40: Janazary (2) | Genzari (1) | F40: ⚠ فيه أسماء محتاجة تتأكد منها بعينك | G40: اخضر جنزاري (5) | جنزاري (4)
...

Sheet Vendoor Dictionary
A1: اسم اللون في Vendoor | B1: الاسم الموحد (English) | C1: عدد الصفوف | D1: إزاي Vendoor كاتبه بالظبط | E1: إزاي اتكتب في شوبيفاي | F1: متسق؟ | G1: ملاحظة
A2: اسود | B2: Black | C2: 446 | D2: اسود (385) | أسود (25) | أسود M (6) | اسود 41 (3) | اسود 42 (3) | اسود 43 (3) | اسود 44 (3) | اسود 45 (3) | اسود XL (2) | اسود L (2) | اسود 2XL (1) | اسود size- (1) | أسود one size (1) | (أسود) (1) | أسود مقاس (1) | أٍسود (1) | أسود ٦سنوات (1) | اسود m (1) | اسود M (1) | اسود 2X (1) | أسود L (1) | E2: Black (435) | Black×Black (2) | Black with Gold (1) | Black with White (1) | اسود (1) | Black × Yellow (1) | أسود (1) | Black with White Sole (1) | White × Black (1) | Black suede (1) | Black & Tiger (1) | F2: ⚠ 11 أسماء
A3: ابيض | B3: White | C3: 227 | D3: ابيض (193) | أبيض (20) | أبيض M (6) | أببض (1) | أبيض مقاس (1) | أبيض ٦سنوات (1) | ابيض m (1) | ابيض M (1) | ابيض L (1) | ابيض XL (1) | ابيض 2X (1) | E3: White (214) | Wihte (5) | Off White (2) | White. (1) | white (1) | ابيض (1) | White × Mauve (1) | White with Black Sole (1) | White with Grey Sole (1) | F3: ⚠ 9 أسماء
A4: رمادي | B4: Gray | C4: 143 | D4: رمادي (127) | رمادي 41 (2) | رمادي 42 (2) | رمادي 43 (2) | رمادي 44 (2) | رمادي 45 (2) | رمادي size- (1) | رمادي مقاس (1) | رمادي M (1) | رمادي L (1) | رمادي XL (1) | رمادي 2X (1) | E4: Gray (115) | Grey (23) | Gray×Black (2) | رمادي (1) | Gray × Pink (1) | White X Gray (1) | F4: ⚠ 6 أسماء
A5: كحلي | B5: Navy | C5: 129 | D5: كحلي (117) | كحلي 41 (2) | كحلي 42 (2) | كحلي 43 (2) | كحلي 44 (2) | كحلي 45 (2) | كحلي ٦سنوات (1) | كحلي m (1) | E5: Navy (125) | Navy×Black (2) | Navy Blue (1) | Burgundy × Navy (1) | F5: ⚠ 4 أسماء
A6: بيج | B6: Beige | C6: 126 | D6: بيج (110) | بيج M (4) | بيچ (1) | بيج size- (1) | بيج 4 (1) | بيج 6 (1) | بيج 8 (1) | بيج 10 (1) | بيج 41 (1) | بيج 42 (1) | بيج 43 (1) | بيج 44 (1) | بيج 45 (1) | بيچ L (1) | E6: Beige (119) | Bagie (2) | Baige (2) | Biege (2) | Burgundy × Olive × Beige (1) | F6: ⚠ 5 أسماء
A7: بني | B7: Brown | C7: 121 | D7: بني (108) | بني 41 (2) | بني 42 (2) | بني 43 (2) | بني 44 (2) | بني 45 (2) | بني 40 (1) | بني L (1) | بنى (1) | E7: Brown (110) | Brwon (4) | Brawn (2) | Havana (1) | بني (1) | Havan (1) | Brown suede (1) | Baige (1) | F7: ⚠ 8 أسماء
A8: هافان | B8: Havana | C8: 54 | D8: هافان (48) | هافان size- (1) | هافان 41 (1) | هافان 42 (1) | هافان 43 (1) | هافان 44 (1) | هافان 45 (1) | E8: Havana (27) | Havan (23) | Havana Brown (3) | هافان (1) | F8: ⚠ 4 أسماء
A9: زيتي | B9: Olive | C9: 53 | D9: زيتى (33) | زيتي (10) | زيتي M (5) | زيتي size- (1) | زيتي مقاس (1) | زيتي L (1) | زيتي XL (1) | زيتي 2X (1) | E9: Olive (36) | Olive Green (13) | Olive×Black (2) | White × Olive (1) | Olive Stars (1) | F9: ⚠ 5 أسماء
A10: ازرق | B10: Blue | C10: 52 | D10: ازرق (46) | أزرق (5) | أزرق L (1) | E10: Blue (48) | White × Blue (2) | White with Blue accents (1) | White With Blue Logo (1) | F10: ⚠ 4 أسماء
A11: احمر | B11: Red | C11: 46 | D11: احمر (37) | أحمر (7) | أحمر XL (1) | أحمر 2XL (1) | E11: Red (45) | White With Red Logo (1) | F11: ⚠ 2 أسماء
A12: جولد | B12: Gold | C12: 40 | D12: جولد (40) | E12: Gold (36) | Cold (1) | Gold – Silver – Rose Gold 18 (1) | Gold 18 (1) | Gold 20 (1) | F12: ⚠ 5 أسماء
A13: بينك | B13: Pink | C13: 30 | D13: بينك (30) | E13: Pink (26) | pink (2) | Light Pink (1) | PINK (1) | F13: ⚠ 4 أسماء
A14: نبيتي | B14: Burgundy | C14: 23 | D14: نبيتي (23) | E14: Burgundy (19) | Burgany (2) | Burgandy (2) | F14: ⚠ 3 أسماء
A15: رصاصي | B15: Gray | C15: 23 | D15: رصاصي (18) | رصاصي 41 (1) | رصاصي 42 (1) | رصاصي 43 (1) | رصاصي 44 (1) | رصاصي 45 (1) | E15: Gray (18) | Grey (3) | Dark Gray (2) | F15: ⚠ 3 أسماء | G15: Vendoor بيستخدم رمادي ورصاصي الاتنين — 17 من 19 في شوبيفاي Gray
A16: اصفر | B16: Yellow | C16: 22 | D16: اصفر (13) | أصفر (5) | أصفر XL (1) | أصفر 2XL (1) | أصفر L (1) | أصفر مقاس (1) | E16: Yellow (21) | yellow (1) | F16: ⚠ 2 أسماء
A17: لبني | B17: Baby Blue | C17: 22 | D17: لبني (20) | لبنى (2) | E17: Baby Blue (15) | Light Blue (7) | F17: ⚠ 2 أسماء | G17: لبني = Baby Blue (15) بس اتكتب Light Blue (7) — لازم اسم واحد
A18: كشمير | B18: Cashmere | C18: 22 | D18: كشمير (21) | كشمير مقاس (1) | E18: Cashmere (13) | Kashmir (8) | Cashmir (1) | F18: ⚠ 3 أسماء
A19: جملي | B19: Camel | C19: 19 | D19: جملي (19) | E19: Camel (15) | Havan (2) | Gamal (1) | Gamel (1) | F19: ⚠ 4 أسماء
A20: بترولي | B20: Petrol | C20: 17 | D20: بترولي (17) | E20: Petrol (13) | Petrol Blue (4) | F20: ⚠ 2 أسماء
A21: مينت جرين | B21: Mint Green | C21: 16 | D21: مينت جرين (16) | E21: Mint Green (15) | Mint (1) | F21: ⚠ 2 أسماء
A22: اخضر | B22: Green | C22: 15 | D22: اخضر (14) | أخضر (1) | E22: Green (14) | White with Green accents (1) | F22: ⚠ 2 أسماء
A23: رمادي فاتح | B23: Light Gray | C23: 14 | D23: رمادي فاتح (14) | E23: Light Grey (8) | Light Gray (5) | Gray (1) | F23: ⚠ 3 أسماء
A24: موف | B24: Mauve | C24: 13 | D24: موف (13) | E24: Mauve (8) | Mouve (3) | Muve (1) | Purple (1) | F24: ⚠ 4 أسماء
A25: اوف وايت | B25: Off White | C25: 13 | D25: اوف وايت (13) | E25: Off White (13) | F25: ✅ اسم واحد
A26: باندل ثلاث قطع | B26: — (مش لون) | C26: 13 | D26: باندل ثلاث قطع (13) | E26: Pack ( Of 3 Pieces) (1) | Pack Of 3 (1) | Pack Of 3 Color ( Black - Burgundy - Coffe ) (1) | Pack Of 3 Color ( Red - Burgundy - Navy ) (1) | Pack Of 3 Color (Beige - Cashmere - Burgandy) (1) | Pack Of 3 Color (Black - Red - Mint) (1) | Pack Of 3 Trunks (1) | Pack of 3 pieces (1) | Pack Of 3 Pieces (1) | Pack (Of 3 Pieces) (1) | Pack of 3 shorts (Black - Beige - Olive) (1) | Pack of 3 shorts (Olive - Dark Gray - Light Gray) (1) | pack Of 3 piece (1) | F26: ⚠ 13 أسماء
A27: رمادي غامق | B27: Dark Gray | C27: 12 | D27: رمادي غامق (12) | E27: Dark Grey (6) | Dark Gray (5) | Dark gray (1) | F27: ⚠ 3 أسماء
A28: رصاصي غامق | B28: Dark Gray | C28: 12 | D28: رصاصي غامق (11) | رصاصي غامق ٦سنوات (1) | E28: Dark Gray (9) | Dark Grey (2) | Gray (1) | F28: ⚠ 3 أسماء
A29: ابيض تطعيم اسود | B29: White & Black | C29: 11 | D29: ابيض تطعيم اسود (11) | E29: White & Black (2) | White With Black (1) | Black * White (1) | White with Black Mark (1) | White with Black (1) | White/Black (1) | White with Black Logo (1) | White (1) | White with Black Accent (1) | White × Black (1) | F29: ⚠ 10 أسماء
... A31: فضي | B31: Silver | C31: 10 | D31: فضي (9) | فضي L (1) | E31: Silver (10) | F31: ✅ اسم واحد
A32: بيبي بلو | B32: Baby Blue | C32: 10 | D32: بيبي بلو (4) | بيبى بلو (1) | بيبي بلو 4 (1) | بيبي بلو 6 (1) | بيبي بلو 8 (1) | بيبي بلو 10 (1) | بيبي بلو مقاس (1) | E32: Baby Blue (10) | F32: ✅ اسم واحد | G32: لبني = Baby Blue (15) بس اتكتب Light Blue (7) — لازم اسم واحد
A33: زتوني | B33: Olive | C33: 7 | D33: زتوني (5) | زتوني XL (1) | زتوني 2XL (1) | E33: Olive Green (6) | Olive (1) | F33: ⚠ 2 أسماء
A34: كافيه | B34: Coffee | C34: 7 | D34: كافيه (6) | كافيه مقاس (1) | E34: Coffee (6) | Caffe (1) | F34: ⚠ 2 أسماء
A35: برجندي | B35: Burgundy | C35: 7 | D35: برجندي (7) | E35: Burgandy (6) | Burgundy (1) | F35: ⚠ 2 أسماء
A36: تركواز | B36: Turquoise | C36: 7 | D36: تركواز (7) | E36: Turquoise (6) | Aqua (1) | F36: ⚠ 2 أسماء
A37: فوشيا | B37: Fuchsia | C37: 7 | D37: فوشيا (6) | فوشيا مقاس (1) | E37: Fuchsia (7) | F37: ✅ اسم واحد
A38: اسود تطعيم ابيض | B38: Black & White | C38: 6 | D38: اسود تطعيم ابيض (6) | E38: Black with White Accent (2) | Black/White (1) | Black With White (1) | Black with White (1) | Black with White Logo (1) | F38: ⚠ 5 أسماء
A39: روز | B39: Rose | C39: 6 | D39: روز (1) | روز 4 (1) | روز 6 (1) | روز 8 (1) | روز 10 (1) | روز L (1) | E39: Pink (4) | Rose (2) | F39: ⚠ 2 أسماء
A40: كيوي | B40: Kiwi | C40: 6 | D40: كيوي 4 (1) | كيوي 6 (1) | كيوي 8 (1) | كيوي 10 (1) | كيوي مقاس (1) | كيوي (1) | E40: Kiwi Green (4) | Kiwi (2) | F40: ⚠ 2 أسماء
A41: بيبسي | B41: Pepsi | C41: 5 | D41: بيبسي (5) | E41: Pepsi (4) | Pepsi Blue (1) | F41: ⚠ 2 أسماء
...

Sheet All Values
A1: القيمة زي ما هي في شوبيفاي | B1: عدد المنتجات | C1: الاسم الموحد المقترح | D1: الحالة | E1: ملاحظة
A2: Aqua | B2: =COUNTIF(Products!$E$2:$E$2033,A2) | C2: Aqua | D2: سليم
A3: Baby Blue | B3: =COUNTIF(Products!$E$2:$E$2033,A3) | C3: Baby Blue | D3: سليم
A4: Baby blue | B4: =COUNTIF(Products!$E$2:$E$2033,A4) | C4: Baby Blue | D4: غلط إملائي/كتابة
A5: Bagie | B5: =COUNTIF(Products!$E$2:$E$2033,A5) | C5: Beige | D5: غلط إملائي/كتابة
A6: Baige | B6: =COUNTIF(Products!$E$2:$E$2033,A6) | C6: Beige | D6: غلط إملائي/كتابة
A7: Beige | B7: =COUNTIF(Products!$E$2:$E$2033,A7) | C7: Beige | D7: سليم
A8: Beige Striped | B8: =COUNTIF(Products!$E$2:$E$2033,A8) | C8: Beige | D8: محتاج تبص عليه بعينك | E8: التفاصيل (Striped) مكانها الوصف مش اسم اللون
A9: Biege | B9: =COUNTIF(Products!$E$2:$E$2033,A9) | C9: Beige | D9: غلط إملائي/كتابة
A10: ييج | B10: =COUNTIF(Products!$E$2:$E$2033,A10) | C10: Beige | D10: عربي ← إنجليزي
A11: Beige x Burgundy | B11: =COUNTIF(Products!$E$2:$E$2033,A11) | C11: Beige & Burgundy | D11: لون مزدوج — توحيد الصيغة
A12: Black | B12: =COUNTIF(Products!$E$2:$E$2033,A12) | C12: Black | D12: سليم
A13: Black & Tiger | B13: =COUNTIF(Products!$E$2:$E$2033,A13) | C13: Black | D13: محتاج تبص عليه بعينك | E13: التفاصيل (Tiger) مكانها الوصف مش اسم اللون
A14: Black Burnished | B14: =COUNTIF(Products!$E$2:$E$2033,A14) | C14: Black | D14: محتاج تبص عليه بعينك | E14: دي خامة/تشطيب مش لون
A15: Black suede | B15: =COUNTIF(Products!$E$2:$E$2033,A15) | C15: Black | D15: محتاج تبص عليه بعينك | E15: دي خامة/تشطيب مش لون
A16: Black with Black Stripes | B16: =COUNTIF(Products!$E$2:$E$2033,A16) | C16: Black | D16: محتاج تبص عليه بعينك | E16: التفاصيل (Stripes) مكانها الوصف مش اسم اللون
A17: Black with Leather Accent | B17: =COUNTIF(Products!$E$2:$E$2033,A17) | C17: Black | D17: محتاج تبص عليه بعينك | E17: التفاصيل (Leather Accent) مكانها الوصف مش اسم اللون
A18: Black×Black | B18: =COUNTIF(Products!$E$2:$E$2033,A18) | C18: Black | D18: اسم تاني لنفس اللون
A19: Matte Black | B19: =COUNTIF(Products!$E$2:$E$2033,A19) | C19: Black | D19: محتاج تبص عليه بعينك | E19: دي خامة/تشطيب مش لون
A20: أسود | B20: =COUNTIF(Products!$E$2:$E$2033,A20) | C20: Black | D20: عربي ← إنجليزي
A21: اسود | B21: =COUNTIF(Products!$E$2:$E$2033,A21) | C21: Black | D21: عربي ← إنجليزي
A22: Black with Beige | B22: =COUNTIF(Products!$E$2:$E$2033,A22) | C22: Black & Beige | D22: لون مزدوج — توحيد الصيغة
A23: Black with Gold | B23: =COUNTIF(Products!$E$2:$E$2033,A23) | C23: Black & Gold | D23: لون مزدوج — توحيد الصيغة
A24: Black with Gold Logo | B24: =COUNTIF(Products!$E$2:$E$2033,A24) | C24: Black & Gold | D24: لون مزدوج — توحيد الصيغة | E24: التفاصيل (Logo) مكانها الوصف مش اسم اللون
A25: Black & Gray | B25: =COUNTIF(Products!$E$2:$E$2033,A25) | C25: Black & Gray | D25: لون مزدوج — توحيد الصيغة
A26: Black with Gray Logo | B26: =COUNTIF(Products!$E$2:$E$2033,A26) | C26: Black & Gray | D26: لون مزدوج — توحيد الصيغة | E26: التفاصيل (Logo) مكانها الوصف مش اسم اللون
A27: Black with Grey | B27: =COUNTIF(Products!$E$2:$E$2033,A27) | C27: Black & Gray | D27: لون مزدوج — توحيد الصيغة
A28: Black with Silver | B28: =COUNTIF(Products!$E$2:$E$2033,A28) | C28: Black & Silver | D28: لون مزدوج — توحيد الصيغة
A29: Black with Silver Stripes | B29: =COUNTIF(Products!$E$2:$E$2033,A29) | C29: Black & Silver | D29: لون مزدوج — توحيد الصيغة | E29: التفاصيل (Stripes) مكانها الوصف مش اسم اللون
A30: Black & White Dual-Face | B30: =COUNTIF(Products!$E$2:$E$2033,A30) | C30: Black & White | D30: لون مزدوج — توحيد الصيغة | E30: التفاصيل (Dual-Face) مكانها الوصف مش اسم اللون
A31: Black * White | B31: =COUNTIF(Products!$E$2:$E$2033,A31) | C31: Black & White | D31: لون مزدوج — توحيد الصيغة
A32: Black With White | B32: =COUNTIF(Products!$E$2:$E$2033,A32) | C32: Black & White | D32: لون مزدوج — توحيد الصيغة
A33: Black with White | B33: =COUNTIF(Products!$E$2:$E$2033,A33) | C33: Black & White | D33: لون مزدوج — توحيد الصيغة
A34: Black with White Accent | B34: =COUNTIF(Products!$E$2:$E$2033,A34) | C34: Black & White | D34: لون مزدوج — توحيد الصيغة | E34: التفاصيل (Accent) مكانها الوصف مش اسم اللون
A35: Black with White Logo | B35: =COUNTIF(Products!$E$2:$E$2033,A35) | C35: Black & White | D35: لون مزدوج — توحيد الصيغة | E35: التفاصيل (Logo) مكانها الوصف مش اسم اللون
A36: Black with White Sole | B36: =COUNTIF(Products!$E$2:$E$2033,A36) | C36: Black & White | D36: لون مزدوج — توحيد الصيغة | E36: التفاصيل (Sole) مكانها الوصف مش اسم اللون
A37: Black with White Stripes | B37: =COUNTIF(Products!$E$2:$E$2033,A37) | C37: Black & White | D37: لون مزدوج — توحيد الصيغة | E37: التفاصيل (Stripes) مكانها الوصف مش اسم اللون
A38: Black/White | B38: =COUNTIF(Products!$E$2:$E$2033,A38) | C38: Black & White | D38: لون مزدوج — توحيد الصيغة
A39: Black × Yellow | B39: =COUNTIF(Products!$E$2:$E$2033,A39) | C39: Black & Yellow | D39: لون مزدوج — توحيد الصيغة
A40: Black Denim | B40: =COUNTIF(Products!$E$2:$E$2033,A40) | C40: Black Denim | D40: سليم
...

Sheet Products
A1: المنتج | B1: Vendor (شوبيفاي) | C1: لينك الأدمن | D1: اسم الـOption | E1: اللون في شوبيفاي | F1: الاسم الموحد المقترح | G1: الحالة | H1: لينك/SKU Vendoor | I1: اللون في Vendoor (يتملى) | J1: ملاحظة | K1: اللون في Vendoor (موحد) | L1: المطابقة | M1: ملاحظة المطابقة
A2: 3-Piece Satin Lingerie Set | B2: Lanramic | C2: فتح | D2: Colors | E2: Black | F2: Black | G2: سليم | H2: https://aff.ven-door.com/product/5732 | I2: — مش موجود على Vendoor | L2: ⛔ اللون مش موجود على Vendoor
A3: 3-Piece Satin Lingerie Set | B3: Lanramic | C3: فتح | D3: Colors | E3: White | F3: White | G3: سليم | H3: https://aff.ven-door.com/product/5732 | I3: ابيض | K3: White | L3: ✅ متطابق
A4: 3-Piece Soft Lounge Set – Bralette, Shorts & Panty | B4: Lanramic | C4: فتح | D4: Colors | E4: Black | F4: Black | G4: سليم | H4: https://aff.ven-door.com/product/3799 | I4: اسود XL / اسود 2XL | K4: Black | L4: ✅ متطابق
A5: 3-Piece Soft Lounge Set – Bralette, Shorts & Panty | B5: Lanramic | C5: فتح | D5: Colors | E5: Olive Green | F5: Olive | G5: محتاج تبص عليه بعينك | H5: https://aff.ven-door.com/product/3799 | I5: زتوني XL / زتوني 2XL | K5: Olive | L5: ✅ متطابق
A6: 3-Piece Soft Lounge Set – Bralette, Shorts & Panty | B6: Lanramic | C6: فتح | D6: Colors | E6: Red | F6: Red | G6: سليم | H6: https://aff.ven-door.com/product/3799 | I6: أحمر XL / أحمر 2XL | K6: Red | L6: ✅ متطابق
A7: 3-Piece Soft Lounge Set – Bralette, Shorts & Panty | B7: Lanramic | C7: فتح | D7: Colors | E7: Yellow | F7: Yellow | G7: سليم | H7: https://aff.ven-door.com/product/3799 | I7: أصفر XL / أصفر 2XL | K7: Yellow | L7: ✅ متطابق
A8: 3D Dinosaur EVA Slipper | B8: Evado | C8: فتح | D8: Colors | E8: Baby Blue | F8: Baby Blue | G8: سليم | H8: https://aff.ven-door.com/product/5875 | I8: لبني | K8: Baby Blue | L8: ✅ متطابق | M8: لبني = Baby Blue (15) بس اتكتب Light Blue (7) — لازم اسم واحد
A9: 3D Dinosaur EVA Slipper | B9: Evado | C9: فتح | D9: Colors | E9: Blue | F9: Blue | G9: سليم | H9: https://aff.ven-door.com/product/5875 | I9: ازرق | K9: Blue | L9: ✅ متطابق
A10: 3D Dinosaur EVA Slipper | B10: Evado | C10: فتح | D10: Colors | E10: Cocoa | F10: Cocoa | G10: محتاج تبص عليه بعينك | H10: https://aff.ven-door.com/product/5879 | I10: كاكاو | K10: Cocoa | L10: ✅ متطابق
A11: 3D Dinosaur EVA Slipper | B11: Evado | C11: فتح | D11: Colors | E11: Green | F11: Green | G11: سليم | H11: https://aff.ven-door.com/product/5879 | I11: اخضر | K11: Green | L11: ✅ متطابق
A12: 3D Dinosaur EVA Slipper | B12: Evado | C12: فتح | D12: Colors | E12: Mauve | F12: Mauve | G12: سليم | H12: https://aff.ven-door.com/product/5875 | I12: موف | K12: Mauve | L12: ✅ متطابق
A13: 3D Dinosaur EVA Slipper | B13: Evado | C13: فتح | D13: Colors | E13: Pink | F13: Pink | G13: سليم | H13: https://aff.ven-door.com/product/5879 | I13: بينك | K13: Pink | L13: ✅ متطابق
A14: 3D Teddy Bear EVA Slipper | B14: Evado | C14: فتح | D14: Colors | E14: Baby Blue | F14: Baby Blue | G14: سليم | H14: https://aff.ven-door.com/product/5877 | I14: لبني | K14: Baby Blue | L14: ✅ متطابق | M14: لبني = Baby Blue (15) بس اتكتب Light Blue (7) — لازم اسم واحد
A15: 3D Teddy Bear EVA Slipper | B15: Evado | C15: فتح | D15: Colors | E15: Blue | F15: Blue | G15: سليم | H15: https://aff.ven-door.com/product/5877 | I15: ازرق | K15: Blue | L15: ✅ متطابق
A16: 3D Teddy Bear EVA Slipper | B16: Evado | C16: فتح | D16: Colors | E16: Brown | F16: Brown | G16: سليم | H16: https://aff.ven-door.com/product/5877 | I16: كاكاو | K16: Cocoa | L16: ❌ مختلف | M16: شوبيفاي: Brown ← Vendoor: كاكاو
A17: 3D Teddy Bear EVA Slipper | B17: Evado | C17: فتح | D17: Colors | E17: Green | F17: Green | G17: سليم | H17: https://aff.ven-door.com/product/5880 | I17: اخضر | K17: Green | L17: ✅ متطابق
A18: 3D Teddy Bear EVA Slipper | B18: Evado | C18: فتح | D18: Colors | E18: Mauve | F18: Mauve | G18: سليم | H18: https://aff.ven-door.com/product/5880 | I18: موف | K18: Mauve | L18: ✅ متطابق
A19: 3D Teddy Bear EVA Slipper | B19: Evado | C19: فتح | D19: Colors | E19: Pink | F19: Pink | G19: سليم | H19: https://aff.ven-door.com/product/5880 | I19: بينك | K19: Pink | L19: ✅ متطابق
A20: 5-Piece Satin Pajama Set | B20: Lanramic | C20: فتح | D20: Color | E20: Burgundy | F20: Burgundy | G20: سليم | H20: https://aff.ven-door.com/product/4890 | I20: نبيتي | K20: Burgundy | L20: ✅ متطابق
A21: 5-Piece Satin Pajama Set | B21: Lanramic | C21: فتح | D21: Color | E21: Olive | F21: Olive | G21: سليم | H21: https://aff.ven-door.com/product/4890 | I21: زيتى | K21: Olive | L21: ✅ متطابق
A22: 5-Piece Satin Pajama Set | B22: Lanramic | C22: فتح | D22: Color | E22: Pink | F22: Pink | G22: سليم | H22: https://aff.ven-door.com/product/4890 | I22: بينك | K22: Pink | L22: ✅ متطابق
A23: 5-Piece Satin Pajama Set | B23: Lanramic | C23: فتح | D23: Color | E23: White. | F23: White | G23: سليم | H23: https://aff.ven-door.com/product/4890 | I23: ابيض | K23: White | L23: ✅ متطابق
A24: Adidas Aqua Comfort Footwear | B24: Gevo | C24: فتح | D24: Color | E24: Beige | F24: Beige | G24: سليم | H24: https://aff.ven-door.com/product/5125 | I24: بيج | K24: Beige | L24: ✅ متطابق
A25: Adidas Aqua Comfort Footwear | B25: Gevo | C25: فتح | D25: Color | E25: Black | F25: Black | G25: سليم | H25: https://aff.ven-door.com/product/5125 | I25: اسود | K25: Black | L25: ✅ متطابق
A26: Adidas Aqua Comfort Footwear | B26: Gevo | C26: فتح | D26: Color | E26: Gray | F26: Gray | G26: سليم | H26: https://aff.ven-door.com/product/5125 | I26: رمادي | K26: Gray | L26: ✅ متطابق
A27: Adidas Aqua Comfort Footwear | B27: Gevo | C27: فتح | D27: Color | E27: Navy | F27: Navy | G27: سليم | H27: https://aff.ven-door.com/product/5125 | I27: كحلي | K27: Navy | L27: ✅ متطابق
A28: Adidas Aqua Comfort Footwear | B28: Gevo | C28: فتح | D28: Color | E28: White | F28: White | G28: سليم | H28: https://aff.ven-door.com/product/5125 | I28: ابيض | K28: White | L28: ✅ متطابق
A29: Adidas Clog Slides | B29: BOB | C29: فتح | D29: Color | E29: Biege | F29: Beige | G29: غلط إملائي/كتابة | H29: https://aff.ven-door.com/product/4816 | I29: — المنتج اتشال من Vendoor (404) | L29: ⛔ المنتج اتشال من Vendoor
A30: Adidas Clog Slides | B30: BOB | C30: فتح | D30: Color | E30: Black | F30: Black | G30: سليم | H30: https://aff.ven-door.com/product/4816 | I30: — المنتج اتشال من Vendoor (404) | L30: ⛔ المنتج اتشال من Vendoor
A31: Adidas Clog Slides | B31: BOB | C31: فتح | D31: Color | E31: Khaki | F31: Khaki | G31: سليم | H31: https://aff.ven-door.com/product/4816 | I31: — المنتج اتشال من Vendoor (404) | L31: ⛔ المنتج اتشال من Vendoor
A32: Adidas Crocodile Sneakers | B32: Birdl | C32: فتح | D32: Colors | E32: Blue | F32: Blue | G32: سليم | H32: https://aff.ven-door.com/product/4993 | I32: ازرق | K32: Blue | L32: ✅ متطابق
A33: Adidas Crocodile Sneakers | B33: Birdl | C33: فتح | D33: Colors | E33: Gray | F33: Gray | G33: سليم | H33: https://aff.ven-door.com/product/4993 | I33: رمادي | K33: Gray | L33: ✅ متطابق
A34: Adidas Crocodile Sneakers | B34: Birdl | C34: فتح | D34: Colors | E34: Red | F34: Red | G34: سليم | H34: https://aff.ven-door.com/product/4993 | I34: احمر | K34: Red | L34: ✅ متطابق
A35: Adidas Crocodile Stars | B35: Birdl | C35: فتح | D35: Colors | E35: Blue | F35: Blue | G35: سليم | H35: https://aff.ven-door.com/product/4991 | I35: ازرق | K35: Blue | L35: ✅ متطابق
A36: Adidas Crocodile Stars | B36: Birdl | C36: فتح | D36: Colors | E36: Gray | F36: Gray | G36: سليم | H36: https://aff.ven-door.com/product/4991 | I36: رمادي | K36: Gray | L36: ✅ متطابق
A37: Adidas Crocodile Stars | B37: Birdl | C37: فتح | D37: Colors | E37: Red | F37: Red | G37: سليم | H37: https://aff.ven-door.com/product/4991 | I37: احمر | K37: Red | L37: ✅ متطابق
A38: Adidas Crocodile Tertan | B38: Birdl | C38: فتح | D38: Colors | E38: Blue | F38: Blue | G38: سليم | H38: https://aff.ven-door.com/product/4992 | I38: ازرق | K38: Blue | L38: ✅ متطابق
A39: Adidas Crocodile Tertan | B39: Birdl | C39: فتح | D39: Colors | E39: Gray | F39: Gray | G39: سليم | H39: https://aff.ven-door.com/product/4992 | I39: رمادي | K39: Gray | L39: ✅ متطابق
A40: Adidas Crocodile Tertan | B40: Birdl | C40: فتح | D40: Colors | E40: Red | F40: Red | G40: سليم | H40: https://aff.ven-door.com/product/4992 | I40: احمر | K40: Red | L40: ✅ متطابق
...

Sheet Option Names
A1: اسم الـOption | B1: عدد المنتجات | C1: المقترح
A2: Size | B2: 550 | C2: ✓ سليم
A3: Color | B3: 368 | C3: ✓ سليم
A4: Colors | B4: 240 | C4: Color
A5: Shoe size | B5: 12 | C5: Size (أو سيبه لو قاصد تفرق مقاسات الجزم)
A6: Title | B6: 5 | C6: منتج من غير variants — سيبه
A7: color | B7: 1 | C7: Color
A8: size | B8: 1 | C8: Size
A9: ColorB | B9: 1 | C9: Color
A10: الالوان | B10: 1 | C10: Color
A11: المقاس | B11: 1 | C11: Size
A13: شوبيفاي بيعمل فلتر منفصل لكل اسم option، فـColor و Colors بيطلعوا للزبون كفلترين. وحّدهم كلهم لـColor.
